{
 "cells": [
  {
   "cell_type": "markdown",
   "id": "618d9dba-2f82-4d84-bf74-98a4e563a15d",
   "metadata": {},
   "source": [
    "# VGG-16"
   ]
  },
  {
   "cell_type": "code",
   "execution_count": 1,
   "id": "e73ca8f9-4520-4af3-80e8-fdf119977e8a",
   "metadata": {},
   "outputs": [],
   "source": [
    "import numpy as np\n",
    "import pandas as pd"
   ]
  },
  {
   "cell_type": "code",
   "execution_count": 2,
   "id": "dd5dfcf3-580c-4253-ac74-5bca584129a9",
   "metadata": {},
   "outputs": [
    {
     "name": "stderr",
     "output_type": "stream",
     "text": [
      "2024-11-08 22:56:43.703715: I tensorflow/core/util/port.cc:153] oneDNN custom operations are on. You may see slightly different numerical results due to floating-point round-off errors from different computation orders. To turn them off, set the environment variable `TF_ENABLE_ONEDNN_OPTS=0`.\n",
      "2024-11-08 22:56:43.711673: E external/local_xla/xla/stream_executor/cuda/cuda_fft.cc:477] Unable to register cuFFT factory: Attempting to register factory for plugin cuFFT when one has already been registered\n",
      "WARNING: All log messages before absl::InitializeLog() is called are written to STDERR\n",
      "E0000 00:00:1731124603.720236    2972 cuda_dnn.cc:8310] Unable to register cuDNN factory: Attempting to register factory for plugin cuDNN when one has already been registered\n",
      "E0000 00:00:1731124603.722893    2972 cuda_blas.cc:1418] Unable to register cuBLAS factory: Attempting to register factory for plugin cuBLAS when one has already been registered\n",
      "2024-11-08 22:56:43.731907: I tensorflow/core/platform/cpu_feature_guard.cc:210] This TensorFlow binary is optimized to use available CPU instructions in performance-critical operations.\n",
      "To enable the following instructions: AVX2 AVX_VNNI FMA, in other operations, rebuild TensorFlow with the appropriate compiler flags.\n"
     ]
    }
   ],
   "source": [
    "import matplotlib.pyplot as plt\n",
    "import tensorflow as tf\n",
    "physical_devices = tf.config.experimental.list_physical_devices('GPU')\n",
    "tf.config.experimental.set_memory_growth(physical_devices[0],\n",
    " True)\n",
    "import keras as K\n",
    "from sklearn.metrics import confusion_matrix, ConfusionMatrixDisplay\n",
    "from sklearn.metrics import classification_report\n",
    "# from tensorflow.keras import datasets, layers, models\n",
    "\n",
    "from tensorflow.keras.models import Sequential\n",
    "from tensorflow.keras.layers import Conv2D, MaxPooling2D, Flatten, Dense"
   ]
  },
  {
   "cell_type": "markdown",
   "id": "f08e4e50-d481-46d5-9c80-1be25bc8e04d",
   "metadata": {},
   "source": [
    "# Preparation for trainning - Train Split"
   ]
  },
  {
   "cell_type": "code",
   "execution_count": 3,
   "id": "fd79802d-0c65-4322-b25e-0beb9a029387",
   "metadata": {},
   "outputs": [
    {
     "name": "stdout",
     "output_type": "stream",
     "text": [
      "Found 7632 files belonging to 8 classes.\n",
      "Using 6106 files for training.\n"
     ]
    },
    {
     "name": "stderr",
     "output_type": "stream",
     "text": [
      "I0000 00:00:1731124607.930974    2972 gpu_device.cc:2022] Created device /job:localhost/replica:0/task:0/device:GPU:0 with 1756 MB memory:  -> device: 0, name: NVIDIA GeForce RTX 3050 Ti Laptop GPU, pci bus id: 0000:01:00.0, compute capability: 8.6\n"
     ]
    }
   ],
   "source": [
    "train_ds = tf.keras.preprocessing.image_dataset_from_directory(\n",
    "    'Dataset of Breast mammography images with Masses/Image After Data Augmentation, Image Size 224x224/',\n",
    "    validation_split=0.2,\n",
    "    subset='training',\n",
    "    seed=123,\n",
    "    image_size=(224, 224),\n",
    "    batch_size=32,\n",
    ")"
   ]
  },
  {
   "cell_type": "code",
   "execution_count": 4,
   "id": "716a08a0-c458-49cd-a8d0-1a9efd764003",
   "metadata": {},
   "outputs": [
    {
     "data": {
      "text/plain": [
       "8"
      ]
     },
     "execution_count": 4,
     "metadata": {},
     "output_type": "execute_result"
    }
   ],
   "source": [
    "classes_ = train_ds.class_names\n",
    "len(classes_)"
   ]
  },
  {
   "cell_type": "code",
   "execution_count": 5,
   "id": "0430155d-5bdc-4ec6-925b-cc5ad5e5e5ed",
   "metadata": {},
   "outputs": [
    {
     "name": "stdout",
     "output_type": "stream",
     "text": [
      "Found 7632 files belonging to 8 classes.\n",
      "Using 1526 files for validation.\n"
     ]
    }
   ],
   "source": [
    "val_ds = tf.keras.preprocessing.image_dataset_from_directory(\n",
    "    'Dataset of Breast mammography images with Masses/Image After Data Augmentation, Image Size 224x224/',\n",
    "    validation_split=0.2,\n",
    "    subset='validation',\n",
    "    seed=123,\n",
    "    image_size=(224, 224),\n",
    "    batch_size=32,\n",
    ")"
   ]
  },
  {
   "cell_type": "code",
   "execution_count": 6,
   "id": "8cde6076-b1c9-4f67-bcac-d1b51a52ac81",
   "metadata": {},
   "outputs": [
    {
     "data": {
      "text/plain": [
       "(<_MapDataset element_spec=(TensorSpec(shape=(None, 224, 224, 3), dtype=tf.float32, name=None), TensorSpec(shape=(None,), dtype=tf.int32, name=None))>,\n",
       " <_MapDataset element_spec=(TensorSpec(shape=(None, 224, 224, 3), dtype=tf.float32, name=None), TensorSpec(shape=(None,), dtype=tf.int32, name=None))>)"
      ]
     },
     "execution_count": 6,
     "metadata": {},
     "output_type": "execute_result"
    }
   ],
   "source": [
    "def normalize(image, label):\n",
    "  return tf.cast(image/255., tf.float32), label\n",
    "\n",
    "train_ds = train_ds.map(normalize)\n",
    "val_ds = val_ds.map(normalize)\n",
    "\n",
    "train_ds, val_ds"
   ]
  },
  {
   "cell_type": "markdown",
   "id": "99ba8d9d-8483-43ae-89e4-3de0bab3eec5",
   "metadata": {},
   "source": [
    "# Preparation for trainning - Test Split"
   ]
  },
  {
   "cell_type": "code",
   "execution_count": 7,
   "id": "23a2b006-11ce-47d8-9575-044adab8f7e8",
   "metadata": {},
   "outputs": [
    {
     "name": "stdout",
     "output_type": "stream",
     "text": [
      "Found 212 files belonging to 8 classes.\n",
      "Using 170 files for training.\n"
     ]
    }
   ],
   "source": [
    "train_ds_test = tf.keras.preprocessing.image_dataset_from_directory(\n",
    "    'Dataset of Breast mammography images with Masses/Image Before Data Augmentation, Image Size 224x224/',\n",
    "    validation_split=0.2,\n",
    "    subset='training',\n",
    "    seed=123,\n",
    "    image_size=(224, 224),\n",
    "    batch_size=32,\n",
    ")"
   ]
  },
  {
   "cell_type": "code",
   "execution_count": 8,
   "id": "2ed6c6f9-e5c6-41bb-9466-84f41a35ff86",
   "metadata": {},
   "outputs": [
    {
     "name": "stdout",
     "output_type": "stream",
     "text": [
      "Found 212 files belonging to 8 classes.\n",
      "Using 42 files for validation.\n"
     ]
    }
   ],
   "source": [
    "val_ds_test = tf.keras.preprocessing.image_dataset_from_directory(\n",
    "    'Dataset of Breast mammography images with Masses/Image Before Data Augmentation, Image Size 224x224/',\n",
    "    validation_split=0.2,\n",
    "    subset='validation',\n",
    "    seed=123,\n",
    "    image_size=(224, 224),\n",
    "    batch_size=32,\n",
    ")"
   ]
  },
  {
   "cell_type": "code",
   "execution_count": 9,
   "id": "91cb6be8-eafb-42df-9939-03e92fa0b5d1",
   "metadata": {},
   "outputs": [
    {
     "data": {
      "text/plain": [
       "(<_MapDataset element_spec=(TensorSpec(shape=(None, 224, 224, 3), dtype=tf.float32, name=None), TensorSpec(shape=(None,), dtype=tf.int32, name=None))>,\n",
       " <_MapDataset element_spec=(TensorSpec(shape=(None, 224, 224, 3), dtype=tf.float32, name=None), TensorSpec(shape=(None,), dtype=tf.int32, name=None))>)"
      ]
     },
     "execution_count": 9,
     "metadata": {},
     "output_type": "execute_result"
    }
   ],
   "source": [
    "def normalize(image, label):\n",
    "  return tf.cast(image/255., tf.float32), label\n",
    "\n",
    "train_ds_test = train_ds_test.map(normalize)\n",
    "val_ds_test = val_ds_test.map(normalize)\n",
    "\n",
    "train_ds_test, val_ds_test"
   ]
  },
  {
   "cell_type": "markdown",
   "id": "27452d16-3cdb-4d6d-b1cd-2c16f14f51c9",
   "metadata": {},
   "source": [
    "# Training"
   ]
  },
  {
   "cell_type": "code",
   "execution_count": 10,
   "id": "6806ac7c-edc9-4238-9254-c23730669a2b",
   "metadata": {
    "scrolled": true
   },
   "outputs": [
    {
     "name": "stderr",
     "output_type": "stream",
     "text": [
      "/home/viviane/apps/anaconda3/envs/pro1-cnn/lib/python3.12/site-packages/keras/src/layers/convolutional/base_conv.py:107: UserWarning: Do not pass an `input_shape`/`input_dim` argument to a layer. When using Sequential models, prefer using an `Input(shape)` object as the first layer in the model instead.\n",
      "  super().__init__(activity_regularizer=activity_regularizer, **kwargs)\n"
     ]
    }
   ],
   "source": [
    "def VGG16(input_shape):\n",
    "  model = Sequential()\n",
    "  \n",
    "  # Block 1\n",
    "  model.add(Conv2D(64, (3, 3), activation='relu', padding='same', input_shape=input_shape))\n",
    "  model.add(Conv2D(64, (3, 3), activation='relu', padding='same'))\n",
    "  model.add(MaxPooling2D((2, 2)))\n",
    "\n",
    "  # Block 2\n",
    "  model.add(Conv2D(128, (3, 3), activation='relu', padding='same'))\n",
    "  model.add(Conv2D(128, (3, 3), activation='relu', padding='same'))\n",
    "  model.add(MaxPooling2D((2, 2)))\n",
    "\n",
    "  # Block 3\n",
    "  model.add(Conv2D(256, (3, 3), activation='relu', padding='same'))\n",
    "  model.add(Conv2D(256, (3, 3), activation='relu', padding='same'))\n",
    "  model.add(Conv2D(256, (3, 3), activation='relu', padding='same'))\n",
    "  model.add(MaxPooling2D((2, 2)))\n",
    "\n",
    "  # Block 4\n",
    "  model.add(Conv2D(512, (3, 3), activation='relu', padding='same'))\n",
    "  model.add(Conv2D(512, (3, 3), activation='relu', padding='same'))\n",
    "  model.add(Conv2D(512, (3, 3), activation='relu', padding='same'))\n",
    "  model.add(MaxPooling2D((2, 2)))\n",
    "\n",
    "  # Block 5\n",
    "  model.add(Conv2D(512, (3, 3), activation='relu', padding='same'))\n",
    "  model.add(Conv2D(512, (3, 3), activation='relu', padding='same'))\n",
    "  model.add(Conv2D(512, (3, 3), activation='relu', padding='same'))\n",
    "  model.add(MaxPooling2D((2, 2)))\n",
    "\n",
    "  # Classifier\n",
    "  model.add(Flatten())\n",
    "  model.add(Dense(4096, activation='relu'))\n",
    "  model.add(Dense(4096, activation='relu'))\n",
    "  model.add(Dense(8, activation='softmax'))\n",
    "\n",
    "  return model\n",
    "\n",
    "model = VGG16(input_shape=(224, 224, 3))"
   ]
  },
  {
   "cell_type": "code",
   "execution_count": 11,
   "id": "b4b3f2a0-058e-4df5-bdba-49ad2e1f3e36",
   "metadata": {},
   "outputs": [],
   "source": [
    "model.compile(optimizer='adam',\n",
    "              loss='SparseCategoricalCrossentropy',\n",
    "              metrics=['accuracy'])"
   ]
  },
  {
   "cell_type": "code",
   "execution_count": 12,
   "id": "c98784ea-d7b3-47be-a4e7-665e9531e517",
   "metadata": {
    "scrolled": true
   },
   "outputs": [
    {
     "name": "stdout",
     "output_type": "stream",
     "text": [
      "Epoch 1/30\n"
     ]
    },
    {
     "name": "stderr",
     "output_type": "stream",
     "text": [
      "WARNING: All log messages before absl::InitializeLog() is called are written to STDERR\n",
      "I0000 00:00:1731124611.257474    3064 service.cc:148] XLA service 0x7f796001ab60 initialized for platform CUDA (this does not guarantee that XLA will be used). Devices:\n",
      "I0000 00:00:1731124611.257521    3064 service.cc:156]   StreamExecutor device (0): NVIDIA GeForce RTX 3050 Ti Laptop GPU, Compute Capability 8.6\n",
      "2024-11-08 22:56:51.331650: I tensorflow/compiler/mlir/tensorflow/utils/dump_mlir_util.cc:268] disabling MLIR crash reproducer, set env var `MLIR_CRASH_REPRODUCER_DIRECTORY` to enable.\n",
      "I0000 00:00:1731124611.553143    3064 cuda_dnn.cc:529] Loaded cuDNN version 90300\n",
      "2024-11-08 22:56:52.301850: I external/local_xla/xla/stream_executor/cuda/cuda_asm_compiler.cc:397] ptxas warning : Registers are spilled to local memory in function 'gemm_fusion_dot_1226_0', 228 bytes spill stores, 228 bytes spill loads\n",
      "\n",
      "2024-11-08 22:56:52.322698: I external/local_xla/xla/stream_executor/cuda/cuda_asm_compiler.cc:397] ptxas warning : Registers are spilled to local memory in function 'gemm_fusion_dot_1226', 196 bytes spill stores, 196 bytes spill loads\n",
      "\n",
      "2024-11-08 22:56:52.578804: W external/local_xla/xla/tsl/framework/bfc_allocator.cc:306] Allocator (GPU_0_bfc) ran out of memory trying to allocate 408.00MiB with freed_by_count=0. The caller indicates that this is not a failure, but this may mean that there could be performance gains if more memory were available.\n",
      "2024-11-08 22:56:52.586270: W tensorflow/core/framework/op_kernel.cc:1841] OP_REQUIRES failed at xla_ops.cc:577 : UNKNOWN: Failed to determine best cudnn convolution algorithm for:\n",
      "%cudnn-conv-bias-activation.39 = (f32[32,64,224,224]{3,2,1,0}, u8[0]{0}) custom-call(f32[32,3,224,224]{3,2,1,0} %bitcast.4706, f32[64,3,3,3]{3,2,1,0} %bitcast.4708, f32[64]{0} %arg3.4), window={size=3x3 pad=1_1x1_1}, dim_labels=bf01_oi01->bf01, custom_call_target=\"__cudnn$convBiasActivationForward\", metadata={op_type=\"Conv2D\" op_name=\"sequential_1/conv2d_1/convolution\" source_file=\"/home/viviane/apps/anaconda3/envs/pro1-cnn/lib/python3.12/site-packages/tensorflow/python/framework/ops.py\" source_line=1196}, backend_config={\"operation_queue_id\":\"0\",\"wait_on_operation_queues\":[],\"cudnn_conv_backend_config\":{\"conv_result_scale\":1,\"activation_mode\":\"kNone\",\"side_input_scale\":0,\"leakyrelu_alpha\":0},\"force_earliest_schedule\":false}\n",
      "\n",
      "Original error: RESOURCE_EXHAUSTED: Out of memory while trying to allocate 427819008 bytes.\n",
      "\n",
      "To ignore this failure and try to use a fallback algorithm (which may have suboptimal performance), use XLA_FLAGS=--xla_gpu_strict_conv_algorithm_picker=false.  Please also file a bug for the root cause of failing autotuning.\n",
      "2024-11-08 22:56:52.586656: I tensorflow/core/framework/local_rendezvous.cc:405] Local rendezvous is aborting with status: UNKNOWN: Failed to determine best cudnn convolution algorithm for:\n",
      "%cudnn-conv-bias-activation.39 = (f32[32,64,224,224]{3,2,1,0}, u8[0]{0}) custom-call(f32[32,3,224,224]{3,2,1,0} %bitcast.4706, f32[64,3,3,3]{3,2,1,0} %bitcast.4708, f32[64]{0} %arg3.4), window={size=3x3 pad=1_1x1_1}, dim_labels=bf01_oi01->bf01, custom_call_target=\"__cudnn$convBiasActivationForward\", metadata={op_type=\"Conv2D\" op_name=\"sequential_1/conv2d_1/convolution\" source_file=\"/home/viviane/apps/anaconda3/envs/pro1-cnn/lib/python3.12/site-packages/tensorflow/python/framework/ops.py\" source_line=1196}, backend_config={\"operation_queue_id\":\"0\",\"wait_on_operation_queues\":[],\"cudnn_conv_backend_config\":{\"conv_result_scale\":1,\"activation_mode\":\"kNone\",\"side_input_scale\":0,\"leakyrelu_alpha\":0},\"force_earliest_schedule\":false}\n",
      "\n",
      "Original error: RESOURCE_EXHAUSTED: Out of memory while trying to allocate 427819008 bytes.\n",
      "\n",
      "To ignore this failure and try to use a fallback algorithm (which may have suboptimal performance), use XLA_FLAGS=--xla_gpu_strict_conv_algorithm_picker=false.  Please also file a bug for the root cause of failing autotuning.\n",
      "\t [[{{node StatefulPartitionedCall}}]]\n"
     ]
    },
    {
     "ename": "UnknownError",
     "evalue": "Graph execution error:\n\nDetected at node StatefulPartitionedCall defined at (most recent call last):\n  File \"/home/viviane/apps/anaconda3/envs/pro1-cnn/lib/python3.12/runpy.py\", line 198, in _run_module_as_main\n\n  File \"/home/viviane/apps/anaconda3/envs/pro1-cnn/lib/python3.12/runpy.py\", line 88, in _run_code\n\n  File \"/home/viviane/apps/anaconda3/envs/pro1-cnn/lib/python3.12/site-packages/ipykernel_launcher.py\", line 18, in <module>\n\n  File \"/home/viviane/apps/anaconda3/envs/pro1-cnn/lib/python3.12/site-packages/traitlets/config/application.py\", line 1075, in launch_instance\n\n  File \"/home/viviane/apps/anaconda3/envs/pro1-cnn/lib/python3.12/site-packages/ipykernel/kernelapp.py\", line 739, in start\n\n  File \"/home/viviane/apps/anaconda3/envs/pro1-cnn/lib/python3.12/site-packages/tornado/platform/asyncio.py\", line 205, in start\n\n  File \"/home/viviane/apps/anaconda3/envs/pro1-cnn/lib/python3.12/asyncio/base_events.py\", line 641, in run_forever\n\n  File \"/home/viviane/apps/anaconda3/envs/pro1-cnn/lib/python3.12/asyncio/base_events.py\", line 1986, in _run_once\n\n  File \"/home/viviane/apps/anaconda3/envs/pro1-cnn/lib/python3.12/asyncio/events.py\", line 88, in _run\n\n  File \"/home/viviane/apps/anaconda3/envs/pro1-cnn/lib/python3.12/site-packages/ipykernel/kernelbase.py\", line 545, in dispatch_queue\n\n  File \"/home/viviane/apps/anaconda3/envs/pro1-cnn/lib/python3.12/site-packages/ipykernel/kernelbase.py\", line 534, in process_one\n\n  File \"/home/viviane/apps/anaconda3/envs/pro1-cnn/lib/python3.12/site-packages/ipykernel/kernelbase.py\", line 437, in dispatch_shell\n\n  File \"/home/viviane/apps/anaconda3/envs/pro1-cnn/lib/python3.12/site-packages/ipykernel/ipkernel.py\", line 362, in execute_request\n\n  File \"/home/viviane/apps/anaconda3/envs/pro1-cnn/lib/python3.12/site-packages/ipykernel/kernelbase.py\", line 778, in execute_request\n\n  File \"/home/viviane/apps/anaconda3/envs/pro1-cnn/lib/python3.12/site-packages/ipykernel/ipkernel.py\", line 449, in do_execute\n\n  File \"/home/viviane/apps/anaconda3/envs/pro1-cnn/lib/python3.12/site-packages/ipykernel/zmqshell.py\", line 549, in run_cell\n\n  File \"/home/viviane/apps/anaconda3/envs/pro1-cnn/lib/python3.12/site-packages/IPython/core/interactiveshell.py\", line 3075, in run_cell\n\n  File \"/home/viviane/apps/anaconda3/envs/pro1-cnn/lib/python3.12/site-packages/IPython/core/interactiveshell.py\", line 3130, in _run_cell\n\n  File \"/home/viviane/apps/anaconda3/envs/pro1-cnn/lib/python3.12/site-packages/IPython/core/async_helpers.py\", line 128, in _pseudo_sync_runner\n\n  File \"/home/viviane/apps/anaconda3/envs/pro1-cnn/lib/python3.12/site-packages/IPython/core/interactiveshell.py\", line 3334, in run_cell_async\n\n  File \"/home/viviane/apps/anaconda3/envs/pro1-cnn/lib/python3.12/site-packages/IPython/core/interactiveshell.py\", line 3517, in run_ast_nodes\n\n  File \"/home/viviane/apps/anaconda3/envs/pro1-cnn/lib/python3.12/site-packages/IPython/core/interactiveshell.py\", line 3577, in run_code\n\n  File \"/tmp/ipykernel_2972/3607109562.py\", line 2, in <module>\n\n  File \"/home/viviane/apps/anaconda3/envs/pro1-cnn/lib/python3.12/site-packages/keras/src/utils/traceback_utils.py\", line 117, in error_handler\n\n  File \"/home/viviane/apps/anaconda3/envs/pro1-cnn/lib/python3.12/site-packages/keras/src/backend/tensorflow/trainer.py\", line 320, in fit\n\n  File \"/home/viviane/apps/anaconda3/envs/pro1-cnn/lib/python3.12/site-packages/keras/src/backend/tensorflow/trainer.py\", line 121, in one_step_on_iterator\n\nFailed to determine best cudnn convolution algorithm for:\n%cudnn-conv-bias-activation.39 = (f32[32,64,224,224]{3,2,1,0}, u8[0]{0}) custom-call(f32[32,3,224,224]{3,2,1,0} %bitcast.4706, f32[64,3,3,3]{3,2,1,0} %bitcast.4708, f32[64]{0} %arg3.4), window={size=3x3 pad=1_1x1_1}, dim_labels=bf01_oi01->bf01, custom_call_target=\"__cudnn$convBiasActivationForward\", metadata={op_type=\"Conv2D\" op_name=\"sequential_1/conv2d_1/convolution\" source_file=\"/home/viviane/apps/anaconda3/envs/pro1-cnn/lib/python3.12/site-packages/tensorflow/python/framework/ops.py\" source_line=1196}, backend_config={\"operation_queue_id\":\"0\",\"wait_on_operation_queues\":[],\"cudnn_conv_backend_config\":{\"conv_result_scale\":1,\"activation_mode\":\"kNone\",\"side_input_scale\":0,\"leakyrelu_alpha\":0},\"force_earliest_schedule\":false}\n\nOriginal error: RESOURCE_EXHAUSTED: Out of memory while trying to allocate 427819008 bytes.\n\nTo ignore this failure and try to use a fallback algorithm (which may have suboptimal performance), use XLA_FLAGS=--xla_gpu_strict_conv_algorithm_picker=false.  Please also file a bug for the root cause of failing autotuning.\n\t [[{{node StatefulPartitionedCall}}]] [Op:__inference_one_step_on_iterator_5638]",
     "output_type": "error",
     "traceback": [
      "\u001b[0;31m---------------------------------------------------------------------------\u001b[0m",
      "\u001b[0;31mUnknownError\u001b[0m                              Traceback (most recent call last)",
      "Cell \u001b[0;32mIn[12], line 2\u001b[0m\n\u001b[1;32m      1\u001b[0m epochs \u001b[38;5;241m=\u001b[39m \u001b[38;5;241m30\u001b[39m\n\u001b[0;32m----> 2\u001b[0m history \u001b[38;5;241m=\u001b[39m model\u001b[38;5;241m.\u001b[39mfit(train_ds,\n\u001b[1;32m      3\u001b[0m                     validation_data\u001b[38;5;241m=\u001b[39mval_ds,\n\u001b[1;32m      4\u001b[0m                     epochs\u001b[38;5;241m=\u001b[39mepochs)\n",
      "File \u001b[0;32m~/apps/anaconda3/envs/pro1-cnn/lib/python3.12/site-packages/keras/src/utils/traceback_utils.py:122\u001b[0m, in \u001b[0;36mfilter_traceback.<locals>.error_handler\u001b[0;34m(*args, **kwargs)\u001b[0m\n\u001b[1;32m    119\u001b[0m     filtered_tb \u001b[38;5;241m=\u001b[39m _process_traceback_frames(e\u001b[38;5;241m.\u001b[39m__traceback__)\n\u001b[1;32m    120\u001b[0m     \u001b[38;5;66;03m# To get the full stack trace, call:\u001b[39;00m\n\u001b[1;32m    121\u001b[0m     \u001b[38;5;66;03m# `keras.config.disable_traceback_filtering()`\u001b[39;00m\n\u001b[0;32m--> 122\u001b[0m     \u001b[38;5;28;01mraise\u001b[39;00m e\u001b[38;5;241m.\u001b[39mwith_traceback(filtered_tb) \u001b[38;5;28;01mfrom\u001b[39;00m \u001b[38;5;28;01mNone\u001b[39;00m\n\u001b[1;32m    123\u001b[0m \u001b[38;5;28;01mfinally\u001b[39;00m:\n\u001b[1;32m    124\u001b[0m     \u001b[38;5;28;01mdel\u001b[39;00m filtered_tb\n",
      "File \u001b[0;32m~/apps/anaconda3/envs/pro1-cnn/lib/python3.12/site-packages/tensorflow/python/eager/execute.py:53\u001b[0m, in \u001b[0;36mquick_execute\u001b[0;34m(op_name, num_outputs, inputs, attrs, ctx, name)\u001b[0m\n\u001b[1;32m     51\u001b[0m \u001b[38;5;28;01mtry\u001b[39;00m:\n\u001b[1;32m     52\u001b[0m   ctx\u001b[38;5;241m.\u001b[39mensure_initialized()\n\u001b[0;32m---> 53\u001b[0m   tensors \u001b[38;5;241m=\u001b[39m pywrap_tfe\u001b[38;5;241m.\u001b[39mTFE_Py_Execute(ctx\u001b[38;5;241m.\u001b[39m_handle, device_name, op_name,\n\u001b[1;32m     54\u001b[0m                                       inputs, attrs, num_outputs)\n\u001b[1;32m     55\u001b[0m \u001b[38;5;28;01mexcept\u001b[39;00m core\u001b[38;5;241m.\u001b[39m_NotOkStatusException \u001b[38;5;28;01mas\u001b[39;00m e:\n\u001b[1;32m     56\u001b[0m   \u001b[38;5;28;01mif\u001b[39;00m name \u001b[38;5;129;01mis\u001b[39;00m \u001b[38;5;129;01mnot\u001b[39;00m \u001b[38;5;28;01mNone\u001b[39;00m:\n",
      "\u001b[0;31mUnknownError\u001b[0m: Graph execution error:\n\nDetected at node StatefulPartitionedCall defined at (most recent call last):\n  File \"/home/viviane/apps/anaconda3/envs/pro1-cnn/lib/python3.12/runpy.py\", line 198, in _run_module_as_main\n\n  File \"/home/viviane/apps/anaconda3/envs/pro1-cnn/lib/python3.12/runpy.py\", line 88, in _run_code\n\n  File \"/home/viviane/apps/anaconda3/envs/pro1-cnn/lib/python3.12/site-packages/ipykernel_launcher.py\", line 18, in <module>\n\n  File \"/home/viviane/apps/anaconda3/envs/pro1-cnn/lib/python3.12/site-packages/traitlets/config/application.py\", line 1075, in launch_instance\n\n  File \"/home/viviane/apps/anaconda3/envs/pro1-cnn/lib/python3.12/site-packages/ipykernel/kernelapp.py\", line 739, in start\n\n  File \"/home/viviane/apps/anaconda3/envs/pro1-cnn/lib/python3.12/site-packages/tornado/platform/asyncio.py\", line 205, in start\n\n  File \"/home/viviane/apps/anaconda3/envs/pro1-cnn/lib/python3.12/asyncio/base_events.py\", line 641, in run_forever\n\n  File \"/home/viviane/apps/anaconda3/envs/pro1-cnn/lib/python3.12/asyncio/base_events.py\", line 1986, in _run_once\n\n  File \"/home/viviane/apps/anaconda3/envs/pro1-cnn/lib/python3.12/asyncio/events.py\", line 88, in _run\n\n  File \"/home/viviane/apps/anaconda3/envs/pro1-cnn/lib/python3.12/site-packages/ipykernel/kernelbase.py\", line 545, in dispatch_queue\n\n  File \"/home/viviane/apps/anaconda3/envs/pro1-cnn/lib/python3.12/site-packages/ipykernel/kernelbase.py\", line 534, in process_one\n\n  File \"/home/viviane/apps/anaconda3/envs/pro1-cnn/lib/python3.12/site-packages/ipykernel/kernelbase.py\", line 437, in dispatch_shell\n\n  File \"/home/viviane/apps/anaconda3/envs/pro1-cnn/lib/python3.12/site-packages/ipykernel/ipkernel.py\", line 362, in execute_request\n\n  File \"/home/viviane/apps/anaconda3/envs/pro1-cnn/lib/python3.12/site-packages/ipykernel/kernelbase.py\", line 778, in execute_request\n\n  File \"/home/viviane/apps/anaconda3/envs/pro1-cnn/lib/python3.12/site-packages/ipykernel/ipkernel.py\", line 449, in do_execute\n\n  File \"/home/viviane/apps/anaconda3/envs/pro1-cnn/lib/python3.12/site-packages/ipykernel/zmqshell.py\", line 549, in run_cell\n\n  File \"/home/viviane/apps/anaconda3/envs/pro1-cnn/lib/python3.12/site-packages/IPython/core/interactiveshell.py\", line 3075, in run_cell\n\n  File \"/home/viviane/apps/anaconda3/envs/pro1-cnn/lib/python3.12/site-packages/IPython/core/interactiveshell.py\", line 3130, in _run_cell\n\n  File \"/home/viviane/apps/anaconda3/envs/pro1-cnn/lib/python3.12/site-packages/IPython/core/async_helpers.py\", line 128, in _pseudo_sync_runner\n\n  File \"/home/viviane/apps/anaconda3/envs/pro1-cnn/lib/python3.12/site-packages/IPython/core/interactiveshell.py\", line 3334, in run_cell_async\n\n  File \"/home/viviane/apps/anaconda3/envs/pro1-cnn/lib/python3.12/site-packages/IPython/core/interactiveshell.py\", line 3517, in run_ast_nodes\n\n  File \"/home/viviane/apps/anaconda3/envs/pro1-cnn/lib/python3.12/site-packages/IPython/core/interactiveshell.py\", line 3577, in run_code\n\n  File \"/tmp/ipykernel_2972/3607109562.py\", line 2, in <module>\n\n  File \"/home/viviane/apps/anaconda3/envs/pro1-cnn/lib/python3.12/site-packages/keras/src/utils/traceback_utils.py\", line 117, in error_handler\n\n  File \"/home/viviane/apps/anaconda3/envs/pro1-cnn/lib/python3.12/site-packages/keras/src/backend/tensorflow/trainer.py\", line 320, in fit\n\n  File \"/home/viviane/apps/anaconda3/envs/pro1-cnn/lib/python3.12/site-packages/keras/src/backend/tensorflow/trainer.py\", line 121, in one_step_on_iterator\n\nFailed to determine best cudnn convolution algorithm for:\n%cudnn-conv-bias-activation.39 = (f32[32,64,224,224]{3,2,1,0}, u8[0]{0}) custom-call(f32[32,3,224,224]{3,2,1,0} %bitcast.4706, f32[64,3,3,3]{3,2,1,0} %bitcast.4708, f32[64]{0} %arg3.4), window={size=3x3 pad=1_1x1_1}, dim_labels=bf01_oi01->bf01, custom_call_target=\"__cudnn$convBiasActivationForward\", metadata={op_type=\"Conv2D\" op_name=\"sequential_1/conv2d_1/convolution\" source_file=\"/home/viviane/apps/anaconda3/envs/pro1-cnn/lib/python3.12/site-packages/tensorflow/python/framework/ops.py\" source_line=1196}, backend_config={\"operation_queue_id\":\"0\",\"wait_on_operation_queues\":[],\"cudnn_conv_backend_config\":{\"conv_result_scale\":1,\"activation_mode\":\"kNone\",\"side_input_scale\":0,\"leakyrelu_alpha\":0},\"force_earliest_schedule\":false}\n\nOriginal error: RESOURCE_EXHAUSTED: Out of memory while trying to allocate 427819008 bytes.\n\nTo ignore this failure and try to use a fallback algorithm (which may have suboptimal performance), use XLA_FLAGS=--xla_gpu_strict_conv_algorithm_picker=false.  Please also file a bug for the root cause of failing autotuning.\n\t [[{{node StatefulPartitionedCall}}]] [Op:__inference_one_step_on_iterator_5638]"
     ]
    }
   ],
   "source": [
    "epochs = 30\n",
    "history = model.fit(train_ds,\n",
    "                    validation_data=val_ds,\n",
    "                    epochs=epochs)"
   ]
  },
  {
   "cell_type": "markdown",
   "id": "71ee495c-a9ae-47fd-a04d-81ce357f9a56",
   "metadata": {},
   "source": [
    "# Evaluating"
   ]
  },
  {
   "cell_type": "code",
   "execution_count": null,
   "id": "dfcc6c62-fb41-4544-875d-fbc41a09c603",
   "metadata": {},
   "outputs": [],
   "source": [
    "history.history"
   ]
  },
  {
   "cell_type": "code",
   "execution_count": null,
   "id": "2b0a5bef-b197-4e72-90c4-00890945f05d",
   "metadata": {},
   "outputs": [],
   "source": [
    "plt.plot(history.history['loss'])\n",
    "plt.plot(history.history['val_loss'])\n",
    "plt.title('Model Loss')\n",
    "plt.ylabel('Loss')\n",
    "plt.xlabel('Epoch')\n",
    "plt.legend(['Train', 'Val'], loc='upper right')\n",
    "plt.show()"
   ]
  },
  {
   "cell_type": "code",
   "execution_count": null,
   "id": "305967a2-2dde-4512-acba-371f1d6d1738",
   "metadata": {},
   "outputs": [],
   "source": [
    "plt.plot(history.history['accuracy'])\n",
    "plt.plot(history.history['val_accuracy'])\n",
    "plt.title('Model Accuracy')\n",
    "plt.ylabel('Accuracy')\n",
    "plt.xlabel('Epoch')\n",
    "plt.legend(['Train', 'Val'], loc='lower right')\n",
    "plt.show()"
   ]
  },
  {
   "cell_type": "code",
   "execution_count": null,
   "id": "923e05d4-7f71-4826-bc55-b8e543c6f2f2",
   "metadata": {},
   "outputs": [],
   "source": [
    "test_loss, test_acc = model.evaluate(val_ds, verbose=2)"
   ]
  },
  {
   "cell_type": "code",
   "execution_count": null,
   "id": "3c48bd9b-711a-4d07-b679-7b2abc98e629",
   "metadata": {},
   "outputs": [],
   "source": [
    "print(test_acc)"
   ]
  },
  {
   "cell_type": "code",
   "execution_count": null,
   "id": "c1d52e46-04b9-457c-8292-22fc27c8d968",
   "metadata": {},
   "outputs": [],
   "source": [
    "predictions = model.predict(train_ds_test)\n",
    "val_pred = np.argmax(predictions, axis=1)"
   ]
  },
  {
   "cell_type": "code",
   "execution_count": null,
   "id": "10b6878d-deda-4b86-9de0-cafab577df6f",
   "metadata": {},
   "outputs": [],
   "source": [
    "y_true = []\n",
    "y_pred = []\n",
    "for images, labels in val_ds_test:\n",
    "  # Make predictions on the batch\n",
    "  batch_pred = model.predict(images)\n",
    "  y_pred.extend(list(batch_pred.argmax(axis=1)))  # Predicted labels\n",
    "  y_true.extend(list(labels.numpy()))  # True labels from the batch\n",
    "\n",
    "# Calculate the confusion matrix\n",
    "cm = confusion_matrix(y_true, y_pred)"
   ]
  },
  {
   "cell_type": "code",
   "execution_count": null,
   "id": "e8e5bfec-e2c5-4a48-af24-6846d027f436",
   "metadata": {},
   "outputs": [],
   "source": [
    "disp = ConfusionMatrixDisplay(cm, display_labels=classes_,)\n",
    "disp.plot()"
   ]
  },
  {
   "cell_type": "code",
   "execution_count": null,
   "id": "87082979-3139-4968-ad16-749df18b2b27",
   "metadata": {},
   "outputs": [],
   "source": [
    "report = classification_report(y_true, y_pred)\n",
    "print(report)"
   ]
  },
  {
   "cell_type": "markdown",
   "id": "9e2265a2-9c32-4546-baec-262578538732",
   "metadata": {},
   "source": [
    "# Save"
   ]
  },
  {
   "cell_type": "code",
   "execution_count": null,
   "id": "5dd9cba5-f892-480f-91c7-7e619ad567ae",
   "metadata": {},
   "outputs": [],
   "source": [
    "# model.save('models/breast_cancer_classification-vgg16.h5')"
   ]
  }
 ],
 "metadata": {
  "kernelspec": {
   "display_name": "Python 3 (ipykernel)",
   "language": "python",
   "name": "python3"
  },
  "language_info": {
   "codemirror_mode": {
    "name": "ipython",
    "version": 3
   },
   "file_extension": ".py",
   "mimetype": "text/x-python",
   "name": "python",
   "nbconvert_exporter": "python",
   "pygments_lexer": "ipython3",
   "version": "3.12.7"
  }
 },
 "nbformat": 4,
 "nbformat_minor": 5
}
